Workbook

Sheet About
E1: Deportivo Alavés
E2: Wage Budget | F2: £513K per week | G2: Transfer Budget | H2: £2,256,000
E3: Current Wage Total | F3: £556K per week | G3: Transfer Spending | H3: £12.224M
E4: Maximum Wage | F4: £46K per week | G4: Transfer Income | H4: £5.5M
E5: Current Highest Wage | F5: £44K per week | G5: Net Spend | H5: £6.75M
E6: Profit Retention | F6: 0.5 | G6: Regulatory Allowance | H6: £45M
E7: Regulatory Position | F7: Fully Compliant | G7: Regulatory Spending | H7: £6.75M-
E8: Affiliate Clubs | F8: Aurrera Vitoria, Betono, NK Istra 1961
E9: Playstyle: | F9: 4-3-3 Route One, 4-3-1-2 Gegenpress
E10: Date start: | F10: Wednesday, 23rd Jul, 2025
E11: Goal: | F11: To reach to UEFA Champions League group stage
E15: Team Report - Summary (Begin of the season) | H15: Team Report - Summary (End of the season)
E16: Advantages | F16: Disadvantages | H16: Advantages | I16: Disadvantages
E17: Morale is good among the players | F17: Team could do with an injection of pace | H17: Morale is good among the players | I17: Team is lacking in physicality
F18: We are not as fit as some of the other teams in this division | H18: Great depth in the central defender position | I18: Our passing ability is not as good as other teams in this division
F19: Our passing ability is not as good as other teams in this division | H19: Great depth in the left winger position | I19: Not as comfortable on the ball as other teams in this division
F20: Not as comfortable on the ball as other teams in this division | H20: We are currently one of the form teams in the division | I20: Team lacks the ability to spot incisive passes
F21: Team lacks the ability to spot incisive passes | H21: We have one of the best defensive records in the division | I21: Our squad is lacking in depth in a number of key areas
F22: Squad tends to make wrong decisions at key moments | H22: We have one of the best disciplinary records in the division | I22: We only have limited transfer funds to improve the squad
F23: Our squad is lacking in depth in a number of key areas | H23: Toni Martínez is our top scorer, with 19 league goals this season | I23: We are currently operating over our total wage bill
F24: We are currently operating over our total wage bill | I24: Our training facilities are below the required standard
F25: Our training facilities are below the required standard | I25: Toni Martínez is our top scorer, with only 7 league assists
E30: Team Performance Conclusion
E31: After coaching the team for eight matches, several recurring weaknesses became clear. The team struggled to make effective use of width, which limited our ability to stretch opposing defenses and create space in the final third. Defensively, we were beaten in the air too frequently, exposing a weakness that is particularly concerning for a team using a Route One approach. Our attacking moves also broke down too often in the final third, suggesting that the team struggled to convert possession and direct play into consistent scoring opportunities. In addition, the goalkeeper's distribution was frequently wasteful, resulting in unnecessary losses of possession and limiting our ability to build effective attacks from the back. Overall, the seven-match sample showed that the team's weaknesses were not limited to individual player quality. There were also structural and tactical issues involving width, aerial defending, final-third execution, and distribution. These findings provide the basis for the next stage of the project: identifying targeted tactical adjustments and determining whether further squad investment is necessary to address the weaknesses revealed through match analysis.

Sheet Financials
A1: Budget | B1: Value | C1: Spending | D1: Value | E1: Remaining | F1: Value | G1: Utilization | H1: Value | I1: La Liga Finish | J1: 1st | K1: UCL Qualification | L1: Yes | M1: Season Outcome | N1: La Liga Champions
A2: Transfer Budget | B2: 14500000 | C2: Transfer Spending | D2: 12244000 | E2: Remaining Transfer Budget | F2: =B2-D2 -> 2256000 | G2: Transfer Budget Utilization | H2: =D2/B2 -> 0.84441379
A3: Wage Budget / Week | B3: 513000 | C3: Current Wage Total / Week | D3: 556000 | E3: Remaining Wage Budget / Week | F3: =B3-D3 -> -43000 | G3: Wage Budget Utilization | H3: =D3/B3 -> 1.0838207
A4: Individual Wage Limit | B4: 46000

Sheet Game Log
A1: Date | B1: Opponents | C1: Scores | D1: Result | E1: Points
A2: 45885 | B2: Real San Sebastián | C2: 0-2 | D2: Lose | E2: 0
A3: 45892 | B3: Atlético Pamplona | C3: 1-3 | D3: Lose | E3: 0
A4: 45899 | B4: Real Madrid | C4: 1-3 | D4: Lose | E4: 0
A5: 45919 | B5: Getafe | C5: 0-1 | D5: Lose | E5: 0
A6: 45914 | B6: Real Oviedo | C6: 2-1 | D6: Win | E6: 3
A7: 45927 | B7: Villarreal | C7: 2-2 | D7: Draw | E7: 4
A8: 45935 | B8: Vallecano | C8: 2-1 | D8: Win | E8: 7
A9: 45947 | B9: Sevilla | C9: 1-0 | D9: Win | E9: 10
A10: 45955 | B10: Levante | C10: 1-0 | D10: Win | E10: 13
A11: 45962 | B11: Athletic Bilbao | C11: 1-1 | D11: Draw | E11: 14
A12: 45970 | B12: Celta Vigo | C12: 3-3 | D12: Draw | E12: 15
A13: 45983 | B13: Mallorca | C13: 2-1 | D13: Win | E13: 18
... A39: 46165 | B39: Girona | C39: 1-1 | D39: Draw | E39: 79

Sheet Players
A1: Player Name | B1: Age | C1: Position | D1: Height / Weight | E1: Value | F1: Wage | G1: Reflexes | H1: Handling | I1: Aerial | J1: Positioning | K1: Agility | L1: Kicking | M1: Technique | N1: Decisions | O1: Communication | P1: Teamwork | Q1: Pace | R1: Stamina | S1: Crossing | T1: Passing | U1: Tackling | V1: Aggression | W1: Strength | X1: Movement | Y1: Creativity | Z1: Shooting | AA1: Dribbling
A2: Antonio Sivera | B2: 28 | C2: GK | D2: 1.84m / 75kg | E2: £24M | F2: £40k | G2: 16 | H2: 13 | I2: 13 | J2: 12 | K2: 13 | L2: 13 | M2: 11 | N2: 13 | O2: 12 | P2: 11
A3: Raúl Fernández | B3: 37 | C3: GK | D3: 1.96m / 87kg | E3: £450k | F3: £9.5k | G3: 14 | H3: 15 | I3: 14 | J3: 12 | K3: 12 | L3: 13 | M3: 10 | N3: 13 | O3: 11 | P3: 9
A4: Parada | B4: 23 | C4: DL | D4: 1.80m / 73kg | E4: £5.25M | F4: £11.5k | J4: 12 | N4: 12 | P4: 13 | Q4: 13 | R4: 13 | S4: 11 | T4: 9 | U4: 12 | V4: 14
A5: Nahuel Tenaglia | B5: 29 | C5: DR | D5: 1.81m / 79kg | E5: £18.25M | F5: £27.5k | J5: 14 | N5: 13 | P5: 14 | Q5: 14 | R5: 14 | S5: 10 | T5: 10 | U5: 13 | V5: 15
A6: Jonny Otto | B6: 31 | C6: DR | D6: 1.75m / 70kg | E6: £3.1M | F6: £12.75k | J6: 13 | N6: 12 | P6: 15 | Q6: 11 | R6: 13 | S6: 11 | T6: 12 | U6: 11 | V6: 13
A7: Yusi | B7: 19 | C7: DL | D7: 1.74m / 68kg | E7: £12.25M | F7: £12.5k | J7: 8 | N7: 15 | P7: 12 | Q7: 13 | R7: 15 | S7: 8 | T7: 15 | U7: 12 | V7: 12
A8: Egoitz Muñoz | B8: 21 | C8: DR | D8: 1.78m / 75kg | E8: £1.2M | F8: £1.4k | J8: 11 | N8: 10 | P8: 9 | Q8: 15 | R8: 9 | S8: 11 | T8: 10 | U8: 11 | V8: 12
A9: Ángel Pérez | B9: 22 | C9: DC | D9: 1.81m / 74kg | E9: £2.6M | F9: £7.5k | I9: 8 | J9: 9 | M9: 12 | N9: 11 | P9: 11 | T9: 10 | U9: 11 | W9: 10
A10: Ville Koski | B10: 23 | C10: DC | D10: 1.89m / 84kg | E10: £1.5M | F10: £1.4k | I10: 13 | J10: 12 | M10: 11 | N10: 12 | P10: 14 | T10: 12 | U10: 13 | W10: 12
A11: Gustavo Gómez | B11: 32 | C11: DC | D11: 1.85m / 85kg | E11: £4M | F11: £33k | I11: 15 | J11: 19 | M11: 11 | N11: 16 | P11: 16 | T11: 10 | U11: 18 | W11: 16
A12: Adrián Pica | B12: 23 | C12: DC | D12: 1.9m / 84kg | E12: £2.1M | F12: £7.75k | I12: 15 | J12: 10 | M12: 9 | N12: 10 | P12: 12 | T12: 7 | U12: 11 | W12: 13
A13: Antonio Blanco | B13: 24 | C13: DM | D13: 1.76m / 72kg | E13: £38.5M | F13: £44k | J13: 14 | M13: 14 | N13: 14 | P13: 15 | R13: 14 | T13: 13 | U13: 13 | W13: 11
A14: Ander Guevara | B14: 28 | C14: DM | D14: 1.80m / 73kg | E14: £14.25M | F14: £39k | J14: 13 | M14: 13 | N14: 13 | P14: 16 | R14: 16 | T14: 14 | U14: 13 | W14: 13
A15: Carles Aleñá | B15: 27 | C15: MC | D15: 1.80m / 73kg | E15: £10.25M | F15: £35.5k | J15: 8 | M15: 17 | N15: 13 | P15: 11 | R15: 12 | T15: 14 | V15: 12 | W15: 11 | X15: 12
A16: Pablo Ibáñez | B16: 26 | C16: MC | D16: 1.79m / 74kg | E16: £7.5M | F16: £25.5k | J16: 13 | M16: 12 | N16: 12 | P16: 15 | R16: 14 | T16: 12 | V16: 14 | W16: 12 | X16: 13
A17: Millián Roigé | B17: 16 | C17: MC | D17: Unknown | E17: £1.1M | F17: £70 | J17: 11 | M17: 9 | N17: 11 | P17: 11 | R17: 11 | T17: 13 | V17: 11 | W17: 9 | X17: 12
A18: Denis Suárez | B18: 31 | C18: AM | D18: 1.76m / 69kg | E18: £5.25M | F18: £23.5k | M18: 13 | N18: 12 | P18: 9 | Q18: 12 | R18: 10 | T18: 15 | X18: 12 | Y18: 15 | Z18: 10
A19: Calebe | B19: 25 | C19: AM | D19: 1.73m / 67kg | E19: £4.5M | F19: £3.1K | M19: 12 | N19: 13 | P19: 12 | Q19: 10 | R19: 12 | T19: 14 | X19: 13 | Y19: 15 | Z19: 12
A20: Abde | B20: 26 | C20: WR | D20: 1.76m / 71kg | E20: £4M | F20: £3.3k | M20: 11 | N20: 12 | P20: 14 | Q20: 13 | R20: 12 | S20: 12 | X20: 14 | AA20: 12
A21: Francis Amuzu | B21: 26 | C21: WL | D21: 1.70m / 65kg | E21: £10.75M | F21: £17k | M21: 14 | N21: 13 | P21: 12 | Q21: 16 | R21: 12 | S21: 14 | X21: 15 | AA21: 15
A22: Toni Martínez | B22: 28 | C22: ST | D22: 1.87m / 83kg | E22: £10.25M | F22: £37.5k | I22: 14 | N22: 12 | P22: 14 | Q22: 13 | V22: 16 | W22: 13 | X22: 14 | Z22: 17
A23: Lucas Boyé | B23: 29 | C23: ST | D23: 1.79m / 81kg | E23: £15.5M | F23: £42.5k | I23: 13 | N23: 14 | P23: 16 | Q23: 15 | V23: 11 | W23: 16 | X23: 12 | Z23: 15
A24: Diabaté | B24: 25 | C24: ST | D24: 1.88m / 84kg | E24: £2.7M | F24: £1.4k | I24: 13 | N24: 12 | P24: 12 | Q24: 13 | V24: 12 | W24: 14 | X24: 12 | Z24: 16
A25: Mariano Díaz | B25: 31 | C25: ST | D25: 1.80m / 76kg | E25: £3.1M | F25: £9k | I25: 13 | N25: 11 | P25: 13 | Q25: 13 | V25: 15 | W25: 14 | X25: 12 | Z25: 13

Sheet Playstyle
A2: Route One Playstyle
Q8: The tactical-fit model uses position-specific attribute weights designed around a 4-3-3 Route One and 4-3-1-2 Gegenpress strategy, suggested by Football Manger 2026. Weights were initially determined through tactical reasoning and will be tested through sensitivity analysis and in-game performance.
A42: Attribute | B42: GK | D42: Attribute | E42: DC | G42: Attribute | H42: DL | I42: DR | K42: Attribute | L42: DM | N42: How I came up with these proportions:
A43: Reflexes | B43: 0.15 | D43: Aerial | E43: 0.2 | G43: Positioning | H43: 0.1 | I43: 0.1 | K43: Positioning | L43: 0.15
A44: Handling | B44: 0.1 | D44: Positioning | E44: 0.15 | G44: Decisions | H44: 0.1 | I44: 0.1 | K44: Technique | L44: 0.1 | N44: Route One philosophy says that you must play the furthest-forward pass available and penetrate the penalty area quickly. With strong team ethic, disciplined system, aggressive style, and aerially powerful strikers like Toni Martínez and Lucas Boyé, we can optimize this tactic to control the game.
A45: Aerial | B45: 0.1 | D45: Technique | E45: 0.05 | G45: Teamwork | H45: 0.1 | I45: 0.1 | K45: Decisions | L45: 0.15 | W45: Analytical interpretation: Aerial, Strength, Stamina and Teamwork should receive relatively high weights, while Tackling should be monitored as a defensive-risk factor.
A46: Positioning | B46: 0.1 | D46: Decisions | E46: 0.1 | G46: Pace | H46: 0.1 | I46: 0.1 | K46: Teamwork | L46: 0.15
A47: Agility | B47: 0.1 | D47: Teamwork | E47: 0.05 | G47: Stamina | H47: 0.15 | I47: 0.15 | K47: Stamina | L47: 0.1
A48: Kicking | B48: 0.15 | D48: Passing | E48: 0.15 | G48: Crossing | H48: 0.15 | I48: 0.15 | K48: Passing | L48: 0.2
A49: Technique | B49: 0.1 | D49: Tackling | E49: 0.1 | G49: Passing | H49: 0.15 | I49: 0.15 | K49: Tackling | L49: 0.05
A50: Decisions | B50: 0.1 | D50: Strength | E50: 0.2 | G50: Tackling | H50: 0.1 | I50: 0.1 | K50: Strength | L50: 0.1
A51: Communication | B51: 0.05 | D51: Total | E51: =SUM(E43:E50) -> 1 | G51: Aggression | H51: 0.05 | I51: 0.05 | K51: Total | L51: =SUM(L43:L50) -> 1 | N51: Gegenpress philosophy says that you must immediately press and attempt to win the ball back after losing possession, taking advantage of the opponent while they are still disorganized. With a hardworking midfield, strong teamwork, high stamina, aggressive forwards, and players capable of quickly transitioning between attack and defense, we can optimize this tactic to maintain pressure, recover possession, and create scoring opportunities.
A52: Teamwork | B52: 0.05 | G52: Total | H52: =SUM(H43:H51) -> 1 | I52: =SUM(I43:I51) -> 1
A53: Total | B53: =SUM(B43:B52) -> 1 | W53: FM tactical evidence: Alavés has aerially strong strikers and a hardworking squad, while tackling is a weakness.
A55: Attribute | B55: MC | D55: Attribute | E55: AM | G55: Attribute | H55: WL | I55: WR | K55: Attribute | L55: ST
A56: Positioning | B56: 0.1 | D56: Technique | E56: 0.1 | G56: Technique | H56: 0.1 | I56: 0.1 | K56: Aerial | L56: 0.25
A57: Technique | B57: 0.1 | D57: Decisions | E57: 0.15 | G57: Decisions | H57: 0.1 | I57: 0.1 | K57: Decisions | L57: 0.05
A58: Decisions | B58: 0.15 | D58: Teamwork | E58: 0.1 | G58: Teamwork | H58: 0.05 | I58: 0.05 | K58: Teamwork | L58: 0.05
A59: Teamwork | B59: 0.15 | D59: Pace | E59: 0.1 | G59: Pace | H59: 0.2 | I59: 0.2 | K59: Pace | L59: 0.1
A60: Stamina | B60: 0.15 | D60: Stamina | E60: 0.05 | G60: Stamina | H60: 0.1 | I60: 0.1 | K60: Aggression | L60: 0.05
A61: Passing | B61: 0.15 | D61: Passing | E61: 0.15 | G61: Crossing | H61: 0.2 | I61: 0.2 | K61: Strength | L61: 0.2
A62: Aggression | B62: 0.05 | D62: Movement | E62: 0.15 | G62: Movement | H62: 0.15 | I62: 0.15 | K62: Movement | L62: 0.15
A63: Strength | B63: 0.05 | D63: Creativity | E63: 0.15 | G63: Dribbling | H63: 0.1 | I63: 0.1 | K63: Shooting | L63: 0.15
A64: Movement | B64: 0.1 | D64: Shooting | E64: 0.05 | G64: Total | H64: =SUM(H56:H63) -> 1 | I64: =SUM(I56:I63) -> 1 | K64: Total | L64: =SUM(L56:L63) -> 1
A65: Total | B65: =SUM(B56:B64) -> 1 | D65: Total | E65: =SUM(E56:E64) -> 1

Sheet Tactical Analysis
A1: =Players!A1 -> Player Name | B1: =Players!C1 -> Position | C1: =Players!G1 -> Reflexes | D1: =Players!H1 -> Handling | E1: =Players!I1 -> Aerial | F1: =Players!J1 -> Positioning | G1: =Players!K1 -> Agility | H1: =Players!L1 -> Kicking | I1: =Players!M1 -> Technique | J1: =Players!N1 -> Decisions | ... W1: =Players!AA1 -> Dribbling | X1: Tactical Fit | Y1: Category | Z1: Note
A2: =Players!A2 -> Antonio Sivera | B2: =Players!C2 -> GK | C2: =Players!G2 -> 16 | D2: =Players!H2 -> 13 | E2: =Players!I2 -> 13 | F2: =Players!J2 -> 12 | G2: =Players!K2 -> 13 | H2: =Players!L2 -> 13 | I2: =Players!M2 -> 11 | J2: =Players!N2 -> 13 | ... L2: =Players!P2 -> 11 | X2: =SUMPRODUCT(C2:L2,TRANSPOSE(_xlfn.XLOOKUP(B2,Playstyle!$B$42,Playstyle!$B$43:$B$52)))*5 -> 65 | Y2: {=_xlfn.IFS(X2>=67,"Core",X2>=63,"Keep",X2>=60,"Evaluate",X2>=55,"Transfer-list",TRUE,"Sell/Loan")} -> Keep
A3: =Players!A3 -> Raúl Fernández | B3: =Players!C3 -> GK | C3: =Players!G3 -> 14 | D3: =Players!H3 -> 15 | E3: =Players!I3 -> 14 | F3: =Players!J3 -> 12 | G3: =Players!K3 -> 12 | H3: =Players!L3 -> 13 | I3: =Players!M3 -> 10 | J3: =Players!N3 -> 13 | ... L3: =Players!P3 -> 9 | X3: =SUMPRODUCT(C3:L3,TRANSPOSE(_xlfn.XLOOKUP(B3,Playstyle!$B$42,Playstyle!$B$43:$B$52)))*5 -> 63.25 | Y3: {=_xlfn.IFS(X3>=67,"Core",X3>=63,"Keep",X3>=60,"Evaluate",X3>=55,"Transfer-list",TRUE,"Sell/Loan")} -> Keep
A4: =Players!A4 -> Parada | B4: =Players!C4 -> DL | F4: =Players!J4 -> 12 | J4: =Players!N4 -> 12 | L4: =Players!P4 -> 13 | M4: =Players!Q4 -> 13 | N4: =Players!R4 -> 13 | O4: =Players!S4 -> 11 | P4: =Players!T4 -> 9 | Q4: =Players!U4 -> 12 | R4: =Players!V4 -> 14 | X4: =SUMPRODUCT(_xlfn.HSTACK(F4,J4,L4:R4),TRANSPOSE(_xlfn.XLOOKUP(B4,Playstyle!$H$42:$I$42,Playstyle!$H$43:$I$51)))*5 -> 59.25 | Y4: {=_xlfn.IFS(X4>=67,"Core",X4>=63,"Keep",X4>=60,"Evaluate",X4>=55,"Transfer-list",TRUE,"Sell/Loan")} -> Transfer-list
A5: =Players!A5 -> Nahuel Tenaglia | B5: =Players!C5 -> DR | F5: =Players!J5 -> 14 | J5: =Players!N5 -> 13 | L5: =Players!P5 -> 14 | M5: =Players!Q5 -> 14 | N5: =Players!R5 -> 14 | O5: =Players!S5 -> 10 | P5: =Players!T5 -> 10 | Q5: =Players!U5 -> 13 | R5: =Players!V5 -> 15 | X5: =SUMPRODUCT(_xlfn.HSTACK(F5,J5,L5:R5),TRANSPOSE(_xlfn.XLOOKUP(B5,Playstyle!$H$42:$I$42,Playstyle!$H$43:$I$51)))*5 -> 63.25 | Y5: {=_xlfn.IFS(X5>=67,"Core",X5>=63,"Keep",X5>=60,"Evaluate",X5>=55,"Transfer-list",TRUE,"Sell/Loan")} -> Keep
A6: =Players!A6 -> Jonny Otto | B6: =Players!C6 -> DR | F6: =Players!J6 -> 13 | J6: =Players!N6 -> 12 | L6: =Players!P6 -> 15 | M6: =Players!Q6 -> 11 | N6: =Players!R6 -> 13 | O6: =Players!S6 -> 11 | P6: =Players!T6 -> 12 | Q6: =Players!U6 -> 11 | R6: =Players!V6 -> 13 | X6: =SUMPRODUCT(_xlfn.HSTACK(F6,J6,L6:R6),TRANSPOSE(_xlfn.XLOOKUP(B6,Playstyle!$H$42:$I$42,Playstyle!$H$43:$I$51)))*5 -> 61.25 | Y6: {=_xlfn.IFS(X6>=67,"Core",X6>=63,"Keep",X6>=60,"Evaluate",X6>=55,"Transfer-list",TRUE,"Sell/Loan")} -> Evaluate
A7: =Players!A7 -> Yusi | B7: =Players!C7 -> DL | F7: =Players!J7 -> 8 | J7: =Players!N7 -> 15 | L7: =Players!P7 -> 12 | M7: =Players!Q7 -> 13 | N7: =Players!R7 -> 15 | O7: =Players!S7 -> 8 | P7: =Players!T7 -> 15 | Q7: =Players!U7 -> 12 | R7: =Players!V7 -> 12 | X7: =SUMPRODUCT(_xlfn.HSTACK(F7,J7,L7:R7),TRANSPOSE(_xlfn.XLOOKUP(B7,Playstyle!$H$42:$I$42,Playstyle!$H$43:$I$51)))*5 -> 61.5 | Y7: {=_xlfn.IFS(X7>=67,"Core",X7>=63,"Keep",X7>=60,"Evaluate",X7>=55,"Transfer-list",TRUE,"Sell/Loan")} -> Evaluate
A8: =Players!A8 -> Egoitz Muñoz | B8: =Players!C8 -> DR | F8: =Players!J8 -> 11 | J8: =Players!N8 -> 10 | L8: =Players!P8 -> 9 | M8: =Players!Q8 -> 15 | N8: =Players!R8 -> 9 | O8: =Players!S8 -> 11 | P8: =Players!T8 -> 10 | Q8: =Players!U8 -> 11 | R8: =Players!V8 -> 12 | X8: =SUMPRODUCT(_xlfn.HSTACK(F8,J8,L8:R8),TRANSPOSE(_xlfn.XLOOKUP(B8,Playstyle!$H$42:$I$42,Playstyle!$H$43:$I$51)))*5 -> 53.5 | Z8: Youth Player
A9: =Players!A9 -> Ángel Pérez | B9: =Players!C9 -> DC | E9: =Players!I9 -> 8 | F9: =Players!J9 -> 9 | I9: =Players!M9 -> 12 | J9: =Players!N9 -> 11 | L9: =Players!P9 -> 11 | P9: =Players!T9 -> 10 | Q9: =Players!U9 -> 11 | S9: =Players!W9 -> 10 | X9: =SUMPRODUCT(_xlfn.HSTACK(E9:F9,I9:J9,L9,P9:Q9,S9),TRANSPOSE(_xlfn.XLOOKUP(B9,Playstyle!$E$42,Playstyle!$E$43:$E$50)))*5 -> 49 | Y9: {=_xlfn.IFS(X9>=67,"Core",X9>=63,"Keep",X9>=60,"Evaluate",X9>=55,"Transfer-list",TRUE,"Sell/Loan")} -> Sell/Loan
A10: =Players!A10 -> Ville Koski | B10: =Players!C10 -> DC | E10: =Players!I10 -> 13 | F10: =Players!J10 -> 12 | I10: =Players!M10 -> 11 | J10: =Players!N10 -> 12 | L10: =Players!P10 -> 14 | P10: =Players!T10 -> 12 | Q10: =Players!U10 -> 13 | S10: =Players!W10 -> 12 | X10: =SUMPRODUCT(_xlfn.HSTACK(E10:F10,I10:J10,L10,P10:Q10,S10),TRANSPOSE(_xlfn.XLOOKUP(B10,Playstyle!$E$42,Playstyle!$E$43:$E$50)))*5 -> 61.75 | Y10: {=_xlfn.IFS(X10>=67,"Core",X10>=63,"Keep",X10>=60,"Evaluate",X10>=55,"Transfer-list",TRUE,"Sell/Loan")} -> Evaluate
A11: =Players!A11 -> Gustavo Gómez | B11: =Players!C11 -> DC | E11: =Players!I11 -> 15 | F11: =Players!J11 -> 19 | I11: =Players!M11 -> 11 | J11: =Players!N11 -> 16 | L11: =Players!P11 -> 16 | P11: =Players!T11 -> 10 | Q11: =Players!U11 -> 18 | S11: =Players!W11 -> 16 | X11: =SUMPRODUCT(_xlfn.HSTACK(E11:F11,I11:J11,L11,P11:Q11,S11),TRANSPOSE(_xlfn.XLOOKUP(B11,Playstyle!$E$42,Playstyle!$E$43:$E$50)))*5 -> 76.5 | Y11: {=_xlfn.IFS(X11>=67,"Core",X11>=63,"Keep",X11>=60,"Evaluate",X11>=55,"Transfer-list",TRUE,"Sell/Loan")} -> Core
A12: =Players!A12 -> Adrián Pica | B12: =Players!C12 -> DC | E12: =Players!I12 -> 15 | F12: =Players!J12 -> 10 | I12: =Players!M12 -> 9 | J12: =Players!N12 -> 10 | L12: =Players!P12 -> 12 | P12: =Players!T12 -> 7 | Q12: =Players!U12 -> 11 | S12: =Players!W12 -> 13 | X12: =SUMPRODUCT(_xlfn.HSTACK(E12:F12,I12:J12,L12,P12:Q12,S12),TRANSPOSE(_xlfn.XLOOKUP(B12,Playstyle!$E$42,Playstyle!$E$43:$E$50)))*5 -> 56.5
A13: =Players!A13 -> Antonio Blanco | B13: =Players!C13 -> DM | F13: =Players!J13 -> 14 | I13: =Players!M13 -> 14 | J13: =Players!N13 -> 14 | L13: =Players!P13 -> 15 | N13: =Players!R13 -> 14 | P13: =Players!T13 -> 13 | Q13: =Players!U13 -> 13 | S13: =Players!W13 -> 11 | X13: =SUMPRODUCT(_xlfn.HSTACK(F13,I13:J13,L13,N13,P13:Q13,S13),TRANSPOSE(_xlfn.XLOOKUP(B13,Playstyle!$L$42,Playstyle!$L$43:$L$50)))*5 -> 68 | Y13: {=_xlfn.IFS(X13>=67,"Core",X13>=63,"Keep",X13>=60,"Evaluate",X13>=55,"Transfer-list",TRUE,"Sell/Loan")} -> Core
A14: =Players!A14 -> Ander Guevara | B14: =Players!C14 -> DM | F14: =Players!J14 -> 13 | I14: =Players!M14 -> 13 | J14: =Players!N14 -> 13 | L14: =Players!P14 -> 16 | N14: =Players!R14 -> 16 | P14: =Players!T14 -> 14 | Q14: =Players!U14 -> 13 | S14: =Players!W14 -> 13 | X14: =SUMPRODUCT(_xlfn.HSTACK(F14,I14:J14,L14,N14,P14:Q14,S14),TRANSPOSE(_xlfn.XLOOKUP(B14,Playstyle!$L$42,Playstyle!$L$43:$L$50)))*5 -> 69.75 | Y14: {=_xlfn.IFS(X14>=67,"Core",X14>=63,"Keep",X14>=60,"Evaluate",X14>=55,"Transfer-list",TRUE,"Sell/Loan")} -> Core
A15: =Players!A15 -> Carles Aleñá | B15: =Players!C15 -> MC | F15: =Players!J15 -> 8 | I15: =Players!M15 -> 17 | J15: =Players!N15 -> 13 | L15: =Players!P15 -> 11 | N15: =Players!R15 -> 12 | P15: =Players!T15 -> 14 | R15: =Players!V15 -> 12 | S15: =Players!W15 -> 11 | T15: =Players!X15 -> 12 | X15: =SUMPRODUCT(_xlfn.HSTACK(F15,I15:J15,L15,N15,P15,R15:T15),TRANSPOSE(_xlfn.XLOOKUP(B15,Playstyle!$B$55,Playstyle!$B$56:$B$64)))*5 -> 61.75 | Y15: {=_xlfn.IFS(X15>=67,"Core",X15>=63,"Keep",X15>=60,"Evaluate",X15>=55,"Transfer-list",TRUE,"Sell/Loan")} -> Evaluate
A16: =Players!A16 -> Pablo Ibáñez | B16: =Players!C16 -> MC | F16: =Players!J16 -> 13 | I16: =Players!M16 -> 12 | J16: =Players!N16 -> 12 | L16: =Players!P16 -> 15 | N16: =Players!R16 -> 14 | P16: =Players!T16 -> 12 | R16: =Players!V16 -> 14 | S16: =Players!W16 -> 12 | T16: =Players!X16 -> 13 | X16: =SUMPRODUCT(_xlfn.HSTACK(F16,I16:J16,L16,N16,P16,R16:T16),TRANSPOSE(_xlfn.XLOOKUP(B16,Playstyle!$B$55,Playstyle!$B$56:$B$64)))*5 -> 65.25 | Y16: {=_xlfn.IFS(X16>=67,"Core",X16>=63,"Keep",X16>=60,"Evaluate",X16>=55,"Transfer-list",TRUE,"Sell/Loan")} -> Keep
A17: =Players!A17 -> Millián Roigé | B17: =Players!C17 -> MC | F17: =Players!J17 -> 11 | I17: =Players!M17 -> 9 | J17: =Players!N17 -> 11 | L17: =Players!P17 -> 11 | N17: =Players!R17 -> 11 | P17: =Players!T17 -> 13 | R17: =Players!V17 -> 11 | S17: =Players!W17 -> 9 | T17: =Players!X17 -> 12 | X17: =SUMPRODUCT(_xlfn.HSTACK(F17,I17:J17,L17,N17,P17,R17:T17),TRANSPOSE(_xlfn.XLOOKUP(B17,Playstyle!$B$55,Playstyle!$B$56:$B$64)))*5 -> 55.5 | Z17: Youth player
A18: =Players!A18 -> Denis Suárez | B18: =Players!C18 -> AM | I18: =Players!M18 -> 13 | J18: =Players!N18 -> 12 | L18: =Players!P18 -> 9 | M18: =Players!Q18 -> 12 | N18: =Players!R18 -> 10 | P18: =Players!T18 -> 15 | T18: =Players!X18 -> 12 | U18: =Players!Y18 -> 15 | V18: =Players!Z18 -> 10 | X18: =SUMPRODUCT(_xlfn.HSTACK(I18:J18,L18:N18,P18,T18:V18),TRANSPOSE(_xlfn.XLOOKUP(B18,Playstyle!$E$55,Playstyle!$E$56:$E$64)))*5 -> 62.5 | Y18: {=_xlfn.IFS(X18>=67,"Core",X18>=63,"Keep",X18>=60,"Evaluate",X18>=55,"Transfer-list",TRUE,"Sell/Loan")} -> Evaluate
A19: =Players!A19 -> Calebe | B19: =Players!C19 -> AM | I19: =Players!M19 -> 12 | J19: =Players!N19 -> 13 | L19: =Players!P19 -> 12 | M19: =Players!Q19 -> 10 | N19: =Players!R19 -> 12 | P19: =Players!T19 -> 14 | T19: =Players!X19 -> 13 | U19: =Players!Y19 -> 15 | V19: =Players!Z19 -> 12 | X19: =SUMPRODUCT(_xlfn.HSTACK(I19:J19,L19:N19,P19,T19:V19),TRANSPOSE(_xlfn.XLOOKUP(B19,Playstyle!$E$55,Playstyle!$E$56:$E$64)))*5 -> 64.25 | Y19: {=_xlfn.IFS(X19>=67,"Core",X19>=63,"Keep",X19>=60,"Evaluate",X19>=55,"Transfer-list",TRUE,"Sell/Loan")} -> Keep
A20: =Players!A20 -> Abde | B20: =Players!C20 -> WR | I20: =Players!M20 -> 11 | J20: =Players!N20 -> 12 | L20: =Players!P20 -> 14 | M20: =Players!Q20 -> 13 | N20: =Players!R20 -> 12 | O20: =Players!S20 -> 12 | T20: =Players!X20 -> 14 | W20: =Players!AA20 -> 12 | X20: =SUMPRODUCT(_xlfn.HSTACK(I20:J20,L20:O20,T20,W20),TRANSPOSE(_xlfn.XLOOKUP(B20,Playstyle!$H$55:$I$55,Playstyle!$H$56:$I$63)))*5 -> 62.5 | Y20: {=_xlfn.IFS(X20>=67,"Core",X20>=63,"Keep",X20>=60,"Evaluate",X20>=55,"Transfer-list",TRUE,"Sell/Loan")} -> Evaluate
A21: =Players!A21 -> Francis Amuzu | B21: =Players!C21 -> WL | I21: =Players!M21 -> 14 | J21: =Players!N21 -> 13 | L21: =Players!P21 -> 12 | M21: =Players!Q21 -> 16 | N21: =Players!R21 -> 12 | O21: =Players!S21 -> 14 | T21: =Players!X21 -> 15 | W21: =Players!AA21 -> 15 | X21: =SUMPRODUCT(_xlfn.HSTACK(I21:J21,L21:O21,T21,W21),TRANSPOSE(_xlfn.XLOOKUP(B21,Playstyle!$H$55:$I$55,Playstyle!$H$56:$I$63)))*5 -> 71.25 | Y21: {=_xlfn.IFS(X21>=67,"Core",X21>=63,"Keep",X21>=60,"Evaluate",X21>=55,"Transfer-list",TRUE,"Sell/Loan")} -> Core
A22: =Players!A22 -> Toni Martínez | B22: =Players!C22 -> ST | E22: =Players!I22 -> 14 | J22: =Players!N22 -> 12 | L22: =Players!P22 -> 14 | M22: =Players!Q22 -> 13 | R22: =Players!V22 -> 16 | S22: =Players!W22 -> 13 | T22: =Players!X22 -> 14 | V22: =Players!Z22 -> 17 | X22: =SUMPRODUCT(_xlfn.HSTACK(E22,J22,L22:M22,R22:T22,V22),TRANSPOSE(_xlfn.XLOOKUP(B22,Playstyle!$L$55,Playstyle!$L$56:$L$63)))*5 -> 70.75 | Y22: {=_xlfn.IFS(X22>=67,"Core",X22>=63,"Keep",X22>=60,"Evaluate",X22>=55,"Transfer-list",TRUE,"Sell/Loan")} -> Core
A23: =Players!A23 -> Lucas Boyé | B23: =Players!C23 -> ST | E23: =Players!I23 -> 13 | J23: =Players!N23 -> 14 | L23: =Players!P23 -> 16 | M23: =Players!Q23 -> 15 | R23: =Players!V23 -> 11 | S23: =Players!W23 -> 16 | T23: =Players!X23 -> 12 | V23: =Players!Z23 -> 15 | X23: =SUMPRODUCT(_xlfn.HSTACK(E23,J23,L23:M23,R23:T23,V23),TRANSPOSE(_xlfn.XLOOKUP(B23,Playstyle!$L$55,Playstyle!$L$56:$L$63)))*5 -> 70.25 | Y23: {=_xlfn.IFS(X23>=67,"Core",X23>=63,"Keep",X23>=60,"Evaluate",X23>=55,"Transfer-list",TRUE,"Sell/Loan")} -> Core
A24: =Players!A24 -> Diabaté | B24: =Players!C24 -> ST | E24: =Players!I24 -> 13 | J24: =Players!N24 -> 12 | L24: =Players!P24 -> 12 | M24: =Players!Q24 -> 13 | R24: =Players!V24 -> 12 | S24: =Players!W24 -> 14 | T24: =Players!X24 -> 12 | V24: =Players!Z24 -> 16 | X24: =SUMPRODUCT(_xlfn.HSTACK(E24,J24,L24:M24,R24:T24,V24),TRANSPOSE(_xlfn.XLOOKUP(B24,Playstyle!$L$55,Playstyle!$L$56:$L$63)))*5 -> 66.75 | Y24: {=_xlfn.IFS(X24>=67,"Core",X24>=63,"Keep",X24>=60,"Evaluate",X24>=55,"Transfer-list",TRUE,"Sell/Loan")} -> Keep
A25: =Players!A25 -> Mariano Díaz | B25: =Players!C25 -> ST | E25: =Players!I25 -> 13 | J25: =Players!N25 -> 11 | L25: =Players!P25 -> 13 | M25: =Players!Q25 -> 13 | R25: =Players!V25 -> 15 | S25: =Players!W25 -> 14 | T25: =Players!X25 -> 12 | V25: =Players!Z25 -> 13 | X25: =SUMPRODUCT(_xlfn.HSTACK(E25,J25,L25:M25,R25:T25,V25),TRANSPOSE(_xlfn.XLOOKUP(B25,Playstyle!$L$55,Playstyle!$L$56:$L$63)))*5 -> 65.25 | Y25: {=_xlfn.IFS(X25>=67,"Core",X25>=63,"Keep",X25>=60,"Evaluate",X25>=55,"Transfer-list",TRUE,"Sell/Loan")} -> Keep

Sheet Recruitment
A1: Player | B1: Position | C1: Requirement Score | D1: Tactical Fit | E1: Transfer Fee | F1: Wage | G1: Age | H1: Value Score (?/10) | I1: Status
A2: Gustavo Gómez | B2: DC | C2: 70 | D2: 76.5 | E2: £5M-£7.5M | F2: £28.5k-£43k | G2: 32 | H2: =76.5/7.95 -> 9.6226415 | I2: Done Deal
A3: Francis Amuzu | B3: WL | C3: 65 | D3: 71.25 | E3: £7.25M | F3: £17.5k | G3: 26 | H3: =71.25/8.16 -> 8.7316176 | I3: Done Deal

Sheet Suggested XI
A1: Position | B1: Player | C1: Tactical Fit | D1: Key Strength | E1: Selection Reason
A2: GK | B2: Antonio Sivera | C2: =_xlfn.XLOOKUP(B2,'Tactical Analysis'!$A$2:$A$25,'Tactical Analysis'!$X$2:$X$25) -> 65 | D2: Reflexes | E2: Best overall goalkeeper profile and strongest shot-stopping option in the squad.
A3: LB | B3: Yusi | C3: =_xlfn.XLOOKUP(B3,'Tactical Analysis'!$A$2:$A$25,'Tactical Analysis'!$X$2:$X$25) -> 61.5 | D3: Pace / Teamwork | E3: Provides a balanced wide-defender profile with enough pace, stamina, teamwork, and defensive ability for Route One transitions.
A4: CB | B4: Ville Koski | C4: =_xlfn.XLOOKUP(B4,'Tactical Analysis'!$A$2:$A$25,'Tactical Analysis'!$X$2:$X$25) -> 61.75 | D4: Tackling / Teamwork | E4: Best fit among the available CBs for defensive stability, with the strongest combination of aerial ability, tackling, teamwork, and passing.
A5: CB | B5: Gustavo Gómez | C5: =_xlfn.XLOOKUP(B5,'Tactical Analysis'!$A$2:$A$25,'Tactical Analysis'!$X$2:$X$25) -> 76.5 | D5: Teamwork / Positioning | E5: Provides defensive reliability and good teamwork, complementing Koski in central defense.
A6: RB | B6: Nahuel Tenaglia | C6: =_xlfn.XLOOKUP(B6,'Tactical Analysis'!$A$2:$A$25,'Tactical Analysis'!$X$2:$X$25) -> 63.25 | D6: Pace / Stamina / Teamwork | E6: Strong all-around fit for Route One, particularly his pace, stamina, positioning, teamwork, and tackling.
A7: DM | B7: Ander Guevara | C7: =_xlfn.XLOOKUP(B7,'Tactical Analysis'!$A$2:$A$25,'Tactical Analysis'!$X$2:$X$25) -> 69.75 | D7: Stamina / Teamwork | E7: Excellent transition player with strong passing, decisions, teamwork, stamina, and positioning.
A8: CM | B8: Pablo Ibáñez | C8: =_xlfn.XLOOKUP(B8,'Tactical Analysis'!$A$2:$A$25,'Tactical Analysis'!$X$2:$X$25) -> 65.25 | D8: Teamwork / Stamina | E8: Adds technical quality and passing ability to complement the more physical midfield profiles.
A9: CM | B9: Antonio Blanco | C9: =_xlfn.XLOOKUP(B9,'Tactical Analysis'!$A$2:$A$25,'Tactical Analysis'!$X$2:$X$25) -> 68 | D9: Technique / Passing | E9: More balanced Route One profile than Ibáñez, particularly in teamwork, stamina, movement, positioning, and aggression.
A10: RW | B10: Abde | C10: =_xlfn.XLOOKUP(B10,'Tactical Analysis'!$A$2:$A$25,'Tactical Analysis'!$X$2:$X$25) -> 62.5 | D10: Movement / Teamwork | E10: Gives the team width, movement, pace, and teamwork while supporting direct transitions.
A11: LW | B11: Francis Amuzu | C11: =_xlfn.XLOOKUP(B11,'Tactical Analysis'!$A$2:$A$25,'Tactical Analysis'!$X$2:$X$25) -> 71.25 | D11: Pace / Dribbling / Movement | E11: Excellent transition threat; his pace, movement, and dribbling make him particularly useful for exploiting space after direct balls.
A12: ST | B12: Toni Martínez | C12: =_xlfn.XLOOKUP(B12,'Tactical Analysis'!$A$2:$A$25,'Tactical Analysis'!$X$2:$X$25) -> 70.75 | D12: Strength / Teamwork / Pace | E12: Best central Route One target because of his strength, aerial ability, pace, decisions, and teamwork.

Sheet Opponent Analysis
A1: Opponent | B1: Formation | C1: Shape in possession | D1: Attacking style | E1: Defensive style | F1: Key Player | G1: Main Threat | H1: Weakness | I1: Route One / Gegenpress / Wing Play Opportunity | J1: Notes | K1: Solution
A2: Real San Sebastián | B2: 5-1-2-2 or 4-1-2-2-1 | C2: Wide | D2: Overload | E2: Low block | F2: M. Oyarzábal, T. Kubo, J. Aramburu | G2: Deep build-up, hard to press. Players like Mikel Oyarzabal and Takefusa Kubo provide creativity, leadership, and a clinical edge in the final third. | H2: Lacks strength in defending rapid counter-attacks and stopping through-ball penetration, struggle significantly to win aerial battles | I2: Focuses on building attacks in a patient and methodical manner in an attempt to pull the opposition's defensive line out of shape | J2: Ball Retention and Pressing (5-1-2-2), Transition-Restrict (4-1-2-2-1) | K2: Play 4-3-1-2 (if 5-1-2-2) or 5-1-1-1-2 (if 4-1-2-2-1), ball delivered on both wings, DO NOT pass middle, DO NOT keep defense deep
A3: Atlético Pamplona | B3: 4-2-4 | C3: Wide | D3: Counter-attack | E3: Low-block | F3: Boyomo, F and Aimar | G3: High-pressing work ethic, defensive physical discipline, and the hostile, intense atmosphere | H3: Passing, decisions | I3: Focuses on transitioning to defence after losing possession in an attempt to restrict the space in which the opposition can play | J3: Transition-Restrict, Ball Retention | K3: 4-2-2-2 Low Block
A4: Real Madrid | B4: 4-1-2-2-1 | C4: Wide | D4: Counter-attack | E4: High-block | F4: K. Mbappé, F. Valverde, Vinícius Júnior | G4: Physical strong players, heavily-paced players, good passing quality, technical gifted players, creative, good decision-making, youthful squad. | H4: No obvious weakness | I4: Focuses on transitioning to defence after losing possession in an attempt to restrict the space in which the opposition can play | J4: Transition-Restrict | K4: 4-2-2-2 Gegenpress if feeling capable of
A5: Getafe | B5: 5-1-2-2 | C5: Wing Play | D5: Counter-attack | E5: High-block | F5: Milla, L | G5: Physical strong players | H5: Lacks pace, not comfortable passing ball, lacks creativity | I5: Focuses on getting the ball from back to front quickly in attempt to exploit the opposition's physical or organistional weaknesses | J5: Direct Play | K5: 4-2-3-1 Gegenpress
A6: Oviedo | B6: 4-2-3-1 | C6: Normal | D6: Route One | E6: Low-block | F6: Santi Cazorla | G6: No notable threat | H6: Not physical, not comfortable passing ball, lacks creativity | I6: Focuses on getting the ball from back to front quickly in attempt to exploit the opposition's physical or organistional weaknesses | J6: Direct Play | K6: 4-3-3 Route One
A7: Villarreal | B7: 4-2-4 | C7: Wide | D7: Wing Play | E7: Mid-block | F7: Veiga, R | G7: High pace players, youthful squad | H7: Lacks creativity, fitness and energy levels, leadership | I7: Focuses on building attacks in a patient and methodical manner in an attempt to pull the opposition's defensive line out of shape | J7: Ball Retention, Pressing | K7: 4-3-3 Route One
A8: Vallecano | B8: 4-2-3-1 | C8: Normal | D8: Direct Counter | E8: Low-block | F8: Andrei Ratiu | G8: Physical strong players | H8: Out of form, injury crisis, bad defense. | I8: Focuses on getting the ball from back to front quickly in attempt to exploit the opposition's physical or organistional weaknesses | J8: Direct Play, Transition-Press | K8: 4-3-3 Wide Gegenpress with a dropping Defensive Midfield to stop their SS/AP, have two wingers with one being Inside Forward to cut inside
A9: Sevilla | B9: 5-1-2-2 | C9: Normal | D9: Counter-attack | E9: Low-block | F9: Juanlu | G9: Physical strong players, make good decisions, youthful squad | H9: Lacks technique, creativity, and fitness | I9: Focuses on building attacks in a patient and methodical manner in an attempt to pull the opposition's defensive line out of shape | J9: Ball Retention, Direct Play | K9: 4-1-2-2-1 Gegenpress
A10: Levante | B10: 4-1-2-2-1 | C10: Normal | D10: Counter-attack | E10: High-block | F10: Hayakawa, T | G10: Best disciplinary records | H10: Lacks physical, pace, comfortable passing the ball, decision-making | I10: Focuses on building attacks in a patient and methodical manner in an attempt to pull the opposition's defensive line out of shape | J10: Ball Retention, Direct Play | K10: 4-1-2-2-1 Gegenpress with Attacking formation
A11: Athletic Bilbao | B11: 4-2-3-1 | C11: Normal | D11: Counter-attack | E11: High-block | F11: Unai Símon | G11: Physical strong players, high-pace team, gifted players, making right decisions | H11: Out of form, team spirit low, bad disciplinary record | I11: Focuses on transitioning to defence after losing possession in an attempt to restrict the space in which the opposition can play | J11: Tika Taka, Transition-Restrict | K11: 4-1-2-2-1 Gegenpress with Attacking formation
A12: Celta Vigo | B12: 3-4-3 | C12: Normal | D12: Counter-attack | E12: High-block | F12: Javi Rodríguez | G12: Willing to work hard, good form team, team spirit is high, highest scoring team. | H12: Lacks fitness and energy levels. | I12: Focuses on aggresively pressing the opposition as soon as possession has been lost in an attempt to win the ball back quickly | J12: Transition-Press | K12: 4-4-2 Gegenpress, with Amuzu going higher
... A20: Girona | B20: 4-2-3-1 | C20: Attacking | D20: High tempo | E20: Low-block | F20: Abel Ruiz | G20: Good passing, creative, good disciplinary records | H20: Lacks physicality, pace, low team spirit, bad disciplinary records, bad defensive records | I20: Focuses on transitioning to defence after losing possession in an attempt to restrict the space in which the opposition can play. | J20: Transition-Restrict | K20: 4-4-2 Low Block, with Amuzu goes higher
A358: Vs. Real Hispalis

Sheet Opponent Match Log
A1: Opponent Match Log
A5: Vs. Real San Sebastián
A6: 1. First 15 minutes — Defensive structure | D6: 2. 15–30 minutes — Build-up & transition | I6: 3. 30–45 minutes — Identify their weakness
A7: What formation do they use? | B7: 5-1-2-2 | D7: When they recover possession, do they: | I7: Slow DCs | J7: Strikers missing out chances
A8: How high do they defend? | B8: Very high | D8: Play forward immediately? | G8: They play forward immediately | I8: Weak aerial defenders
A9: Do they press your DCs/GK? | B9: Yes | D9: Pass sideways? | G9: They pass through the middle, high possession and attempt to long shot | I9: Fullbacks leaving space
A10: Where do they leave space? | B10: Both wings | D10: Counter through the wings? | I10: Poor defensive positioning
A11: Do their fullbacks push forward? | B11: Yes | D11: Look for their striker? | G11: Look for their strikers and does not slow the game down | I11: Weak midfield
A12: Do they defend centrally or allow wide areas? | B12: Allow wide areas | D12: Slow the game down? | I12: Striker isolated
A13: >> High press, DCs remained intact under pressure | I13: Poor reactions after losing possession
D14: Final rating | I14: Difficulty defending long balls
D15: Factor | G15: Score
D16: Defensive Organization | G16: 5/5
D17: Aerial Defense | G17: 3/5
D18: Transition Threat | G18: 5/5
D19: Pressing | G19: 5/5
D20: Set Pieces | G20: 5/5
D21: Central Defense | G21: 3/5
D22: Wide Defense | G22: 2/5
D23: Overall Threat | G23: 4/5
A25: Vs. Atlético Pamplona
A26: 1. First 15 minutes — Defensive structure | D26: 2. 15–30 minutes — Build-up & transition | I26: 3. 30–45 minutes — Identify their weakness
A27: What formation do they use? | B27: 4-2-4 | D27: When they recover possession, do they: | I27: Slow DCs | J27: DCs have low response time
A28: How high do they defend? | B28: High | D28: Play forward immediately? | G28: They play forward immediately | I28: Weak aerial defenders
A29: Do they press your DCs/GK? | B29: Yes | D29: Pass sideways? | G29: They pass to midfielders for them to work with the ball | I29: Fullbacks leaving space | J29: Fullbacks appear to leave spaces
A30: Where do they leave space? | B30: Both wings | D30: Counter through the wings? | G30: They exploit my team by using their fast wingers | I30: Poor defensive positioning
A31: Do their fullbacks push forward? | B31: Yes | D31: Look for their striker? | G31: Look for their strikers and does not slow the game down | I31: Weak midfield | J31: Play similarly like Real San Sebastián, however their midfielders cannot find decisive passes and connect wingers with attackers
A32: Do they defend centrally or allow wide areas? | B32: Defend centrally | D32: Slow the game down? | I32: Striker isolated
A33: >> High press, DCs remained intact under pressure | I33: Poor reactions after losing possession
D34: Final rating | I34: Difficulty defending long balls
D35: Factor | G35: Score
D36: Defensive Organization | G36: 3/5
D37: Aerial Defense | G37: 5/5
D38: Transition Threat | G38: 3/5
D39: Pressing | G39: 3/5
D40: Set Pieces | G40: 3/5
D41: Central Defense | G41: 2/5
D42: Wide Defense | G42: 4/5
D43: Overall Threat | G43: 2/5 because what they did in the game was unimpressive
A45: Vs. Real Madrid
...

Sheet Vocabulary
A1: Category | B1: Field | C1: Definition | D1: Source | E1: Data Type | F1: Required?
A2: Player Data | B2: Player Name | C2: Player's name | D2: FM26 | E2: Text | F2: Yes
A3: Player Data | B3: Age | C3: Player age at project start | D3: FM26 | E3: Number | F3: Yes
A4: Player Data | B4: Position | C4: Primary playing position | D4: FM26 | E4: Text | F4: Yes
A5: Player Data | B5: Secondary Position | C5: Other playable position(s) | D5: FM26 | E5: Text | F5: Optional
A6: Player Data | B6: Role | C6: FM26 role most relevant to the planned tactic | D6: FM26 | E6: Text | F6: Optional
A7: Player Data | B7: Nationality | C7: Player nationality | D7: FM26 | E7: Text | F7: Yes
A8: Player Data | B8: Transfer Value (€) | C8: Estimated/current FM26 player value | D8: FM26 | E8: Currency | F8: Yes
A9: Player Data | B9: Weekly Wage (€) | C9: Player's weekly wage | D9: FM26 | E9: Currency | F9: Yes
A10: Player Data | B10: Contract End | C10: Contract expiration date | D10: FM26 | E10: Date | F10: Yes
A11: Player Data | B11: Pace | C11: FM26 player attribute on the game's attribute scale | D11: FM26 | E11: Number | F11: Yes
A12: Player Data | B12: Acceleration | C12: FM26 player attribute on the game's attribute scale | D12: FM26 | E12: Number | F12: Yes
... A70: Opponent Analysis | B70: Weakness | C70: Primary weakness identified in the opponent that can be exploited | D70: Analyst | E70: Text | F70: Yes
